Workbook

Sheet aida
A1: Anno | B1: 31/12/2024 | C1: 31/12/2023 | D1: 31/12/2022 | E1: 31/12/2021 | F1: 31/12/2020 | G1: 31/12/2019 | H1: 31/12/2018 | I1: 31/12/2017
A2: A. CREDITI VERSO SOCI | B2: 0 | C2: 0 | D2: 0 | E2: 0 | F2: 0 | G2: 0 | H2: 0 | I2: 0
A3: Quota di capitale richiamata | B3: 0 | C3: 0 | D3: 0 | E3: 0 | F3: 0 | G3: 0 | H3: 0 | I3: 0
A4: B. TOTALE IMMOBILIZZAZIONI sep.ind. Di quelle conc. In loc. Finanz. | B4: 8842950 | C4: 9182852 | D4: 9614947 | E4: 9565702 | F4: 7073181 | G4: 2616289 | H4: 1201123 | I4: 908499
A5: B.I. TOTALE IMMOB. IMMATERIALI | B5: 89523 | C5: 106380 | D5: 139717 | E5: 76490 | F5: 33453 | G5: 7543 | H5: 0 | I5: 1977
A6: B.I.1. Costi impianto e ampl. | B6: 0 | C6: 0 | D6: 0 | E6: 0 | F6: 0 | G6: 0 | H6: 0 | I6: 0
A7: B.I.2. Costi ricerca e pubb. | B7: 0 | C7: 0 | D7: 0 | E7: 0 | F7: 0 | G7: 0 | H7: 0 | I7: 0
A8: B.I.3. Diritti brevetto ind. | B8: 64590 | C8: 97381 | D8: 130172 | E8: 3968 | F8: 4960 | G8: 0 | H8: 0 | I8: 0
A9: B.I.4. Concessioni, licenze | B9: 8453 | C9: 8999 | D9: 9545 | E9: 0 | F9: 0 | G9: 0 | H9: 0 | I9: 0
A10: B.I.5. Avviamento/Differenza di consolidamento | B10: 0 | C10: 0 | D10: 0 | E10: 0 | F10: 0 | G10: 0 | H10: 0 | I10: 0
A11: di cui: Avviamento | B11: 0 | C11: 0 | D11: 0 | E11: 0 | F11: 0 | G11: 0 | H11: 0 | I11: 0
A12: B.I.6. Imm. in corso | B12: 0 | C12: 0 | D12: 0 | E12: 67622 | F12: 28493 | G12: 7543 | H12: 0 | I12: 0
A13: B.I.7. Altre immobiliz. Immateriali | B13: 16480 | C13: 0 | D13: 0 | E13: 4900 | F13: 0 | G13: 0 | H13: 0 | I13: 1977
... A93: TOTALE ATTIVO | B93: 18790859 | C93: 20554377 | D93: 20723060 | E93: 18204611 | F93: 14795011 | G93: 9311398 | H93: 6455031 | I93: 6151737
A94: Passivo
A95: PATRIMONIO NETTO
A96: A. TOTALE PATRIMONIO NETTO | B96: 5757287 | C96: 5227552 | D96: 4660887 | E96: 4082303 | F96: 3206001 | G96: 2384718 | H96: 1733081 | I96: 1062658
A97: A.I. Capitale sociale | B97: 140000 | C97: 140000 | D97: 140000 | E97: 140000 | F97: 140000 | G97: 140000 | H97: 140000 | I97: 140000
A98: di cui: Versamenti soci in c/capitale | B98: 0 | C98: 0 | D98: 0 | E98: 0 | F98: 0 | G98: 0 | H98: 0 | I98: 0
A99: di cui: Versamenti in c/futuro aumento di capitale | B99: 0 | C99: 0 | D99: 0 | E99: 0 | F99: 0 | G99: 0 | H99: 0 | I99: 0
A100: di cui: Versamenti in c/capitale | B100: 0 | C100: 0 | D100: 0 | E100: 0 | F100: 0 | G100: 0 | H100: 0 | I100: 0
A101: di cui: Versamenti a copertura perdite | B101: 0 | C101: 0 | D101: 0 | E101: 0 | F101: 0 | G101: 0 | H101: 0 | I101: 0
A102: A.II. Riserva da sovrapprezzo | B102: 0 | C102: 0 | D102: 0 | E102: 0 | F102: 0 | G102: 0 | H102: 0 | I102: 0
A103: A.III. Riserva di rivalutazione | B103: 0 | C103: 0 | D103: 0 | E103: 0 | F103: 0 | G103: 0 | H103: 0 | I103: 0
A104: A.IV. Riserva legale | B104: 28000 | C104: 28000 | D104: 28000 | E104: 28000 | F104: 28000 | G104: 28000 | H104: 18237 | I104: 0
A105: A.V. Riserva statutaria | B105: 0 | C105: 0 | D105: 0 | E105: 0 | F105: 0 | G105: 0 | H105: 0 | I105: 0
A106: Riserva azioni proprie | B106: 0 | C106: 0 | D106: 0 | E106: 0 | F106: 0 | G106: 0 | H106: 0 | I106: 0
A107: A.VI. Altre riserve | B107: 4689554 | C107: 4492885 | D107: 3814306 | E107: 2953000 | F107: 2116719 | G107: 1465082 | H107: 904419 | I107: -1
... A126: C. TRATTAMENTO DI FINE RAPPORTO | B126: 191675 | C126: 179286 | D126: 189098 | E126: 197380 | F126: 174392 | G126: 206556 | H126: 187238 | I126: 173667
A127: Debiti
A128: D. TOTALE DEBITI | B128: 11906052 | C128: 13914499 | D128: 14618344 | E128: 13815442 | F128: 11347602 | G128: 6671454 | H128: 4468030 | I128: 4868877
A129: D.1. Obblig.ni entro | B129: 0 | C129: 0 | D129: 0 | E129: 0 | F129: 0 | G129: 0 | H129: 0 | I129: 0
A130: D.1. Obblig.ni oltre | B130: 0 | C130: 0 | D130: 0 | E130: 0 | F130: 0 | G130: 0 | H130: 0 | I130: 0
A131: D.2. Obblig.ni convert. entro | B131: 0 | C131: 0 | D131: 0 | E131: 0 | F131: 0 | G131: 0 | H131: 0 | I131: 0
A132: D.2. Obblig.ni convert. oltre. | B132: 0 | C132: 0 | D132: 0 | E132: 0 | F132: 0 | G132: 0 | H132: 0 | I132: 0
A133: D.3. Soci per Finanziamenti entro | B133: 0 | C133: 0 | D133: 0 | E133: 0 | F133: 0 | G133: 0 | H133: 0 | I133: 0
A134: D.3. Soci per Finanziamenti oltre | B134: 0 | C134: 0 | D134: 0 | E134: 0 | F134: 0 | G134: 0 | H134: 0 | I134: 0
A135: D.4. Banche entro l'esercizio | B135: 3395294 | C135: 3987523 | D135: 4519420 | E135: 3495062 | F135: 2923930 | G135: 3390744 | H135: 1825267 | I135: 1954310
A136: D.4. Banche oltre l'esercizio | B136: 5110204 | C136: 6691873 | D136: 6691933 | E136: 7333471 | F136: 6304053 | G136: 588287 | H136: 808395 | I136: 952264
A137: D.5. Altri finanziatori entro | B137: 435 | C137: 435 | D137: 435 | E137: 435 | F137: 310 | G137: 0 | H137: 120 | I137: 0
...

Sheet case
A1: SP attivo | B1: =aida!B1 -> 31/12/2024 | C1: =aida!C1 -> 31/12/2023 | D1: =aida!D1 -> 31/12/2022 | E1: =aida!E1 -> 31/12/2021 | F1: =aida!F1 -> 31/12/2020 | G1: =aida!G1 -> 31/12/2019 | H1: =aida!H1 -> 31/12/2018 | I1: =aida!I1 -> 31/12/2017 | K1: Segno | L1: Riclassificazione
A2: =aida!A2 -> A. CREDITI VERSO SOCI | B2: =$K2*aida!B2 -> 0 | C2: =$K2*aida!C2 -> 0 | D2: =$K2*aida!D2 -> 0 | E2: =$K2*aida!E2 -> 0 | F2: =$K2*aida!F2 -> 0 | G2: =$K2*aida!G2 -> 0 | H2: =$K2*aida!H2 -> 0 | I2: =$K2*aida!I2 -> 0 | K2: -1 | L2: Finanziamenti netti vs soci e controllanti
A3: =aida!A3 -> Quota di capitale richiamata | B3: =$K3*aida!B3 -> 0 | C3: =$K3*aida!C3 -> 0 | D3: =$K3*aida!D3 -> 0 | E3: =$K3*aida!E3 -> 0 | F3: =$K3*aida!F3 -> 0 | G3: =$K3*aida!G3 -> 0 | H3: =$K3*aida!H3 -> 0 | I3: =$K3*aida!I3 -> 0 | K3: 1
A5: =aida!A4 -> B. TOTALE IMMOBILIZZAZIONI sep.ind. Di quelle conc. In loc. Finanz. | B5: =$K5*aida!B4 -> 8842950 | C5: =$K5*aida!C4 -> 9182852 | D5: =$K5*aida!D4 -> 9614947 | E5: =$K5*aida!E4 -> 9565702 | F5: =$K5*aida!F4 -> 7073181 | G5: =$K5*aida!G4 -> 2616289 | H5: =$K5*aida!H4 -> 1201123 | I5: =$K5*aida!I4 -> 908499 | K5: 1
A6: =aida!A5 -> B.I. TOTALE IMMOB. IMMATERIALI | B6: =$K6*aida!B5 -> 89523 | C6: =$K6*aida!C5 -> 106380 | D6: =$K6*aida!D5 -> 139717 | E6: =$K6*aida!E5 -> 76490 | F6: =$K6*aida!F5 -> 33453 | G6: =$K6*aida!G5 -> 7543 | H6: =$K6*aida!H5 -> 0 | I6: =$K6*aida!I5 -> 1977 | K6: 1 | L6: Immobilizzazioni immateriali nette
A7: =aida!A6 -> B.I.1. Costi impianto e ampl. | B7: =$K7*aida!B6 -> 0 | C7: =$K7*aida!C6 -> 0 | D7: =$K7*aida!D6 -> 0 | E7: =$K7*aida!E6 -> 0 | F7: =$K7*aida!F6 -> 0 | G7: =$K7*aida!G6 -> 0 | H7: =$K7*aida!H6 -> 0 | I7: =$K7*aida!I6 -> 0 | K7: 1
A8: =aida!A7 -> B.I.2. Costi ricerca e pubb. | B8: =$K8*aida!B7 -> 0 | C8: =$K8*aida!C7 -> 0 | D8: =$K8*aida!D7 -> 0 | E8: =$K8*aida!E7 -> 0 | F8: =$K8*aida!F7 -> 0 | G8: =$K8*aida!G7 -> 0 | H8: =$K8*aida!H7 -> 0 | I8: =$K8*aida!I7 -> 0 | K8: 1
A9: =aida!A8 -> B.I.3. Diritti brevetto ind. | B9: =$K9*aida!B8 -> 64590 | C9: =$K9*aida!C8 -> 97381 | D9: =$K9*aida!D8 -> 130172 | E9: =$K9*aida!E8 -> 3968 | F9: =$K9*aida!F8 -> 4960 | G9: =$K9*aida!G8 -> 0 | H9: =$K9*aida!H8 -> 0 | I9: =$K9*aida!I8 -> 0 | K9: 1
A10: =aida!A9 -> B.I.4. Concessioni, licenze | B10: =$K10*aida!B9 -> 8453 | C10: =$K10*aida!C9 -> 8999 | D10: =$K10*aida!D9 -> 9545 | E10: =$K10*aida!E9 -> 0 | F10: =$K10*aida!F9 -> 0 | G10: =$K10*aida!G9 -> 0 | H10: =$K10*aida!H9 -> 0 | I10: =$K10*aida!I9 -> 0 | K10: 1
A11: =aida!A10 -> B.I.5. Avviamento/Differenza di consolidamento | B11: =$K11*aida!B10 -> 0 | C11: =$K11*aida!C10 -> 0 | D11: =$K11*aida!D10 -> 0 | E11: =$K11*aida!E10 -> 0 | F11: =$K11*aida!F10 -> 0 | G11: =$K11*aida!G10 -> 0 | H11: =$K11*aida!H10 -> 0 | I11: =$K11*aida!I10 -> 0 | K11: 1
A12: =aida!A11 -> di cui: Avviamento | B12: =$K12*aida!B11 -> 0 | C12: =$K12*aida!C11 -> 0 | D12: =$K12*aida!D11 -> 0 | E12: =$K12*aida!E11 -> 0 | F12: =$K12*aida!F11 -> 0 | G12: =$K12*aida!G11 -> 0 | H12: =$K12*aida!H11 -> 0 | I12: =$K12*aida!I11 -> 0 | K12: 1
A13: =aida!A12 -> B.I.6. Imm. in corso | B13: =$K13*aida!B12 -> 0 | C13: =$K13*aida!C12 -> 0 | D13: =$K13*aida!D12 -> 0 | E13: =$K13*aida!E12 -> 67622 | F13: =$K13*aida!F12 -> 28493 | G13: =$K13*aida!G12 -> 7543 | H13: =$K13*aida!H12 -> 0 | I13: =$K13*aida!I12 -> 0 | K13: 1
A14: =aida!A13 -> B.I.7. Altre immobiliz. Immateriali | B14: =$K14*aida!B13 -> 16480 | C14: =$K14*aida!C13 -> 0 | D14: =$K14*aida!D13 -> 0 | E14: =$K14*aida!E13 -> 4900 | F14: =$K14*aida!F13 -> 0 | G14: =$K14*aida!G13 -> 0 | H14: =$K14*aida!H13 -> 0 | I14: =$K14*aida!I13 -> 1977 | K14: 1
A15: =aida!A14 -> Fondo amm.to Immob. Immateriali | B15: =$K15*aida!B14 -> 0 | C15: =$K15*aida!C14 -> 0 | D15: =$K15*aida!D14 -> 0 | E15: =$K15*aida!E14 -> 0 | F15: =$K15*aida!F14 -> 0 | G15: =$K15*aida!G14 -> 0 | H15: =$K15*aida!H14 -> 0 | I15: =$K15*aida!I14 -> 0 | K15: 1
A16: =aida!A15 -> B.II. TOTALE IMMOB. MATERIALI | B16: =$K16*aida!B15 -> 8694725 | C16: =$K16*aida!C15 -> 9017770 | D16: =$K16*aida!D15 -> 9416528 | E16: =$K16*aida!E15 -> 9430510 | F16: =$K16*aida!F15 -> 7025024 | G16: =$K16*aida!G15 -> 2594042 | H16: =$K16*aida!H15 -> 1186419 | I16: =$K16*aida!I15 -> 891818 | K16: 1 | L16: Immobilizzazioni materiali nette
A17: =aida!A16 -> di cui: Beni materiali concessi in locazione finanziaria | B17: =$K17*aida!B16 -> 0 | C17: =$K17*aida!C16 -> 0 | D17: =$K17*aida!D16 -> 0 | E17: =$K17*aida!E16 -> 0 | F17: =$K17*aida!F16 -> 0 | G17: =$K17*aida!G16 -> 0 | H17: =$K17*aida!H16 -> 0 | I17: =$K17*aida!I16 -> 0 | K17: 1
A18: =aida!A17 -> B.II.1. Terreni e fabbricati | B18: =$K18*aida!B17 -> 6069102 | C18: =$K18*aida!C17 -> 6328571 | D18: =$K18*aida!D17 -> 6543383 | E18: =$K18*aida!E17 -> 6374984 | F18: =$K18*aida!F17 -> 396319 | G18: =$K18*aida!G17 -> 412628 | H18: =$K18*aida!H17 -> 418736 | I18: =$K18*aida!I17 -> 324645 | K18: 1
A19: =aida!A18 -> B.II.2. Impianti | B19: =$K19*aida!B18 -> 1774810 | C19: =$K19*aida!C18 -> 2137598 | D19: =$K19*aida!D18 -> 2352511 | E19: =$K19*aida!E18 -> 2232169 | F19: =$K19*aida!F18 -> 1801043 | G19: =$K19*aida!G18 -> 258024 | H19: =$K19*aida!H18 -> 302043 | I19: =$K19*aida!I18 -> 336024 | K19: 1
A20: =aida!A19 -> B.II.3. Attrez. industriali | B20: =$K20*aida!B19 -> 197170 | C20: =$K20*aida!C19 -> 187192 | D20: =$K20*aida!D19 -> 184756 | E20: =$K20*aida!E19 -> 168289 | F20: =$K20*aida!F19 -> 141111 | G20: =$K20*aida!G19 -> 110856 | H20: =$K20*aida!H19 -> 130147 | I20: =$K20*aida!I19 -> 133231 | K20: 1
A21: =aida!A20 -> B.II.4. Altri beni | B21: =$K21*aida!B20 -> 177873 | C21: =$K21*aida!C20 -> 244518 | D21: =$K21*aida!D20 -> 312178 | E21: =$K21*aida!E20 -> 236539 | F21: =$K21*aida!F20 -> 116965 | G21: =$K21*aida!G20 -> 45295 | H21: =$K21*aida!H20 -> 68843 | I21: =$K21*aida!I20 -> 97918 | K21: 1
A22: =aida!A21 -> B.II.5. Imm. in corso/acconti | B22: =$K22*aida!B21 -> 475770 | C22: =$K22*aida!C21 -> 119891 | D22: =$K22*aida!D21 -> 23700 | E22: =$K22*aida!E21 -> 418529 | F22: =$K22*aida!F21 -> 4569586 | G22: =$K22*aida!G21 -> 1767239 | H22: =$K22*aida!H21 -> 266650 | I22: =$K22*aida!I21 -> 0 | K22: 1
A23: =aida!A22 -> Fondo amm.to Immob. Materiali | B23: =$K23*aida!B22 -> 0 | C23: =$K23*aida!C22 -> 0 | D23: =$K23*aida!D22 -> 0 | E23: =$K23*aida!E22 -> 0 | F23: =$K23*aida!F22 -> 0 | G23: =$K23*aida!G22 -> 0 | H23: =$K23*aida!H22 -> 0 | I23: =$K23*aida!I22 -> 0 | K23: 1
A24: =aida!A23 -> B.III. TOTALE IMMOB. FINANZIARIE | B24: =$K24*aida!B23 -> 58702 | C24: =$K24*aida!C23 -> 58702 | D24: =$K24*aida!D23 -> 58702 | E24: =$K24*aida!E23 -> 58702 | F24: =$K24*aida!F23 -> 14704 | G24: =$K24*aida!G23 -> 14704 | H24: =$K24*aida!H23 -> 14704 | I24: =$K24*aida!I23 -> 14704 | K24: 1
A25: =aida!A24 -> di cui: esigibili entro l'esercizio successivo | B25: =$K25*aida!B24 -> 0 | C25: =$K25*aida!C24 -> 0 | D25: =$K25*aida!D24 -> 0 | E25: =$K25*aida!E24 -> 0 | F25: =$K25*aida!F24 -> 8192 | G25: =$K25*aida!G24 -> 8192 | H25: =$K25*aida!H24 -> 8192 | I25: =$K25*aida!I24 -> 0 | K25: 1
A26: =aida!A25 -> B.III.1. TOT Partecipazioni | B26: =$K26*aida!B25 -> 58702 | C26: =$K26*aida!C25 -> 58702 | D26: =$K26*aida!D25 -> 58702 | E26: =$K26*aida!E25 -> 58702 | F26: =$K26*aida!F25 -> 6512 | G26: =$K26*aida!G25 -> 6512 | H26: =$K26*aida!H25 -> 6512 | I26: =$K26*aida!I25 -> 6512 | K26: 1
A27: =aida!A26 -> B.III.1.a. Imprese controllate | B27: =$K27*aida!B26 -> 0 | C27: =$K27*aida!C26 -> 0 | D27: =$K27*aida!D26 -> 0 | E27: =$K27*aida!E26 -> 0 | F27: =$K27*aida!F26 -> 0 | G27: =$K27*aida!G26 -> 0 | H27: =$K27*aida!H26 -> 0 | I27: =$K27*aida!I26 -> 0 | K27: 1 | L27: Partecipazioni
A28: =aida!A27 -> B.III.1.b. Imprese collegate | B28: =$K28*aida!B27 -> 0 | C28: =$K28*aida!C27 -> 0 | D28: =$K28*aida!D27 -> 0 | E28: =$K28*aida!E27 -> 0 | F28: =$K28*aida!F27 -> 0 | G28: =$K28*aida!G27 -> 0 | H28: =$K28*aida!H27 -> 0 | I28: =$K28*aida!I27 -> 0 | K28: 1 | L28: Partecipazioni
A29: =aida!A28 -> B.III.1.c. Imprese controllanti | B29: =$K29*aida!B28 -> 0 | C29: =$K29*aida!C28 -> 0 | D29: =$K29*aida!D28 -> 0 | E29: =$K29*aida!E28 -> 0 | F29: =$K29*aida!F28 -> 0 | G29: =$K29*aida!G28 -> 0 | H29: =$K29*aida!H28 -> 0 | I29: =$K29*aida!I28 -> 0 | K29: 1 | L29: Azioni proprie e partecipazioni in controllanti
A30: =aida!A29 -> B.III.1.d. In imprese sottoposte al controllo delle controllanti | B30: =$K30*aida!B29 -> 0 | C30: =$K30*aida!C29 -> 0 | D30: =$K30*aida!D29 -> 0 | E30: =$K30*aida!E29 -> 0 | F30: =$K30*aida!F29 -> 0 | G30: =$K30*aida!G29 -> 0 | H30: =$K30*aida!H29 -> 0 | I30: =$K30*aida!I29 -> 0 | K30: 1 | L30: Partecipazioni
A31: =aida!A30 -> B.III.1.d.bis. Altre imprese | B31: =$K31*aida!B30 -> 58702 | C31: =$K31*aida!C30 -> 58702 | D31: =$K31*aida!D30 -> 58702 | E31: =$K31*aida!E30 -> 58702 | F31: =$K31*aida!F30 -> 6512 | G31: =$K31*aida!G30 -> 6512 | H31: =$K31*aida!H30 -> 6512 | I31: =$K31*aida!I30 -> 6512 | K31: 1 | L31: Partecipazioni
A32: =aida!A31 -> B.III.2. TOT CREDITI Imm. Fin. | B32: =$K32*aida!B31 -> 0 | C32: =$K32*aida!C31 -> 0 | D32: =$K32*aida!D31 -> 0 | E32: =$K32*aida!E31 -> 0 | F32: =$K32*aida!F31 -> 8192 | G32: =$K32*aida!G31 -> 8192 | H32: =$K32*aida!H31 -> 8192 | I32: =$K32*aida!I31 -> 8192 | K32: 1
A33: =aida!A32 -> B.III.2.a. Cred. vs Controllate entro | B33: =$K33*aida!B32 -> 0 | C33: =$K33*aida!C32 -> 0 | D33: =$K33*aida!D32 -> 0 | E33: =$K33*aida!E32 -> 0 | F33: =$K33*aida!F32 -> 0 | G33: =$K33*aida!G32 -> 0 | H33: =$K33*aida!H32 -> 0 | I33: =$K33*aida!I32 -> 0 | K33: 1 | L33: Crediti vs controllate e collegate
A34: =aida!A33 -> B.III.2.a. Cred. vs Controllate oltre | B34: =$K34*aida!B33 -> 0 | C34: =$K34*aida!C33 -> 0 | D34: =$K34*aida!D33 -> 0 | E34: =$K34*aida!E33 -> 0 | F34: =$K34*aida!F33 -> 0 | G34: =$K34*aida!G33 -> 0 | H34: =$K34*aida!H33 -> 0 | I34: =$K34*aida!I33 -> 0 | K34: 1 | L34: Crediti vs controllate e collegate
A35: =aida!A34 -> B.III.2.b. Cred. vs Collegate entro | B35: =$K35*aida!B34 -> 0 | C35: =$K35*aida!C34 -> 0 | D35: =$K35*aida!D34 -> 0 | E35: =$K35*aida!E34 -> 0 | F35: =$K35*aida!F34 -> 0 | G35: =$K35*aida!G34 -> 0 | H35: =$K35*aida!H34 -> 0 | I35: =$K35*aida!I34 -> 0 | K35: 1 | L35: Crediti vs controllate e collegate
A36: =aida!A35 -> B.III.2.b. Cred. vs Collegate oltre | B36: =$K36*aida!B35 -> 0 | C36: =$K36*aida!C35 -> 0 | D36: =$K36*aida!D35 -> 0 | E36: =$K36*aida!E35 -> 0 | F36: =$K36*aida!F35 -> 0 | G36: =$K36*aida!G35 -> 0 | H36: =$K36*aida!H35 -> 0 | I36: =$K36*aida!I35 -> 0 | K36: 1 | L36: Crediti vs controllate e collegate
A37: =aida!A36 -> B.III.2.c. Cred. vs Controllanti entro | B37: =$K37*aida!B36 -> 0 | C37: =$K37*aida!C36 -> 0 | D37: =$K37*aida!D36 -> 0 | E37: =$K37*aida!E36 -> 0 | F37: =$K37*aida!F36 -> 0 | G37: =$K37*aida!G36 -> 0 | H37: =$K37*aida!H36 -> 0 | I37: =$K37*aida!I36 -> 0 | K37: 1 | L37: Immobilizzazioni extra-operative
A38: =aida!A37 -> B.III.2.c. Cred. vs Controllanti oltre | B38: =$K38*aida!B37 -> 0 | C38: =$K38*aida!C37 -> 0 | D38: =$K38*aida!D37 -> 0 | E38: =$K38*aida!E37 -> 0 | F38: =$K38*aida!F37 -> 0 | G38: =$K38*aida!G37 -> 0 | H38: =$K38*aida!H37 -> 0 | I38: =$K38*aida!I37 -> 0 | K38: 1 | L38: Immobilizzazioni extra-operative
A39: =aida!A38 -> B.III.2.d. Cred. vs imprese sottoposte al controllo delle controllanti entro | B39: =$K39*aida!B38 -> 0 | C39: =$K39*aida!C38 -> 0 | D39: =$K39*aida!D38 -> 0 | E39: =$K39*aida!E38 -> 0 | F39: =$K39*aida!F38 -> 0 | G39: =$K39*aida!G38 -> 0 | H39: =$K39*aida!H38 -> 0 | I39: =$K39*aida!I38 -> 0 | K39: 1 | L39: Crediti diversi
A40: =aida!A39 -> B.III.2.d. Cred. vs imprese sottoposte al controllo delle controllanti oltre | B40: =$K40*aida!B39 -> 0 | C40: =$K40*aida!C39 -> 0 | D40: =$K40*aida!D39 -> 0 | E40: =$K40*aida!E39 -> 0 | F40: =$K40*aida!F39 -> 0 | G40: =$K40*aida!G39 -> 0 | H40: =$K40*aida!H39 -> 0 | I40: =$K40*aida!I39 -> 0 | K40: 1 | L40: Crediti diversi
A41: =aida!A40 -> B.III.2.d.bis. Cred. vs Altri entro | B41: =$K41*aida!B40 -> 0 | C41: =$K41*aida!C40 -> 0 | D41: =$K41*aida!D40 -> 0 | E41: =$K41*aida!E40 -> 0 | F41: =$K41*aida!F40 -> 8192 | G41: =$K41*aida!G40 -> 8192 | H41: =$K41*aida!H40 -> 8192 | I41: =$K41*aida!I40 -> 0 | K41: 1 | L41: Crediti diversi
...

Sheet RC
B2: Stato Patrimoniale Attivo | C2: =case!B1 -> 31/12/2024 | D2: =case!C1 -> 31/12/2023 | E2: =case!D1 -> 31/12/2022 | F2: =case!E1 -> 31/12/2021 | G2: =case!F1 -> 31/12/2020 | H2: =case!G1 -> 31/12/2019 | I2: =case!H1 -> 31/12/2018 | J2: =case!I1 -> 31/12/2017
B3: Attività operative
B4: Attività operative correnti
B5: Crediti verso clienti | C5: =SUMIF(case!$L:$L,$B5,case!B:B) -> 4256399 | D5: =SUMIF(case!$L:$L,$B5,case!C:C) -> 3896776 | E5: =SUMIF(case!$L:$L,$B5,case!D:D) -> 2966203 | F5: =SUMIF(case!$L:$L,$B5,case!E:E) -> 3180616 | G5: =SUMIF(case!$L:$L,$B5,case!F:F) -> 2787212 | H5: =SUMIF(case!$L:$L,$B5,case!G:G) -> 2642901 | I5: =SUMIF(case!$L:$L,$B5,case!H:H) -> 2353521 | J5: =SUMIF(case!$L:$L,$B5,case!I:I) -> 2381302
B6: Magazzino | C6: =SUMIF(case!$L:$L,$B6,case!B:B) -> 4608814 | D6: =SUMIF(case!$L:$L,$B6,case!C:C) -> 5040346 | E6: =SUMIF(case!$L:$L,$B6,case!D:D) -> 5250264 | F6: =SUMIF(case!$L:$L,$B6,case!E:E) -> 2924371 | G6: =SUMIF(case!$L:$L,$B6,case!F:F) -> 2556678 | H6: =SUMIF(case!$L:$L,$B6,case!G:G) -> 3010721 | I6: =SUMIF(case!$L:$L,$B6,case!H:H) -> 2422241 | J6: =SUMIF(case!$L:$L,$B6,case!I:I) -> 2070635
B7: Altre attività operative correnti | C7: =SUMIF(case!$L:$L,$B7,case!B:B) -> 816992 | D7: =SUMIF(case!$L:$L,$B7,case!C:C) -> 1399880 | E7: =SUMIF(case!$L:$L,$B7,case!D:D) -> 1028451 | F7: =SUMIF(case!$L:$L,$B7,case!E:E) -> 116979 | G7: =SUMIF(case!$L:$L,$B7,case!F:F) -> 104609 | H7: =SUMIF(case!$L:$L,$B7,case!G:G) -> 261767 | I7: =SUMIF(case!$L:$L,$B7,case!H:H) -> 83114 | J7: =SUMIF(case!$L:$L,$B7,case!I:I) -> 73755
B8: Totale attività operative correnti | C8: =SUM(C5:C7) -> 9682205 | D8: =SUM(D5:D7) -> 10337002 | E8: =SUM(E5:E7) -> 9244918 | F8: =SUM(F5:F7) -> 6221966 | G8: =SUM(G5:G7) -> 5448499 | H8: =SUM(H5:H7) -> 5915389 | I8: =SUM(I5:I7) -> 4858876 | J8: =SUM(J5:J7) -> 4525692
B9: Immobilizzazioni operative nette
B10: Immobilizzazioni materiali nette | C10: =SUMIF(case!$L:$L,$B10,case!B:B) -> 8694725 | D10: =SUMIF(case!$L:$L,$B10,case!C:C) -> 9017770 | E10: =SUMIF(case!$L:$L,$B10,case!D:D) -> 9416528 | F10: =SUMIF(case!$L:$L,$B10,case!E:E) -> 9430510 | G10: =SUMIF(case!$L:$L,$B10,case!F:F) -> 7025024 | H10: =SUMIF(case!$L:$L,$B10,case!G:G) -> 2594042 | I10: =SUMIF(case!$L:$L,$B10,case!H:H) -> 1186419 | J10: =SUMIF(case!$L:$L,$B10,case!I:I) -> 891818
B11: Immobilizzazioni immateriali nette | C11: =SUMIF(case!$L:$L,$B11,case!B:B) -> 89523 | D11: =SUMIF(case!$L:$L,$B11,case!C:C) -> 106380 | E11: =SUMIF(case!$L:$L,$B11,case!D:D) -> 139717 | F11: =SUMIF(case!$L:$L,$B11,case!E:E) -> 76490 | G11: =SUMIF(case!$L:$L,$B11,case!F:F) -> 33453 | H11: =SUMIF(case!$L:$L,$B11,case!G:G) -> 7543 | I11: =SUMIF(case!$L:$L,$B11,case!H:H) -> 0 | J11: =SUMIF(case!$L:$L,$B11,case!I:I) -> 1977
B12: Totale immobilizzazioni operative nette | C12: =SUM(C10:C11) -> 8784248 | D12: =SUM(D10:D11) -> 9124150 | E12: =SUM(E10:E11) -> 9556245 | F12: =SUM(F10:F11) -> 9507000 | G12: =SUM(G10:G11) -> 7058477 | H12: =SUM(H10:H11) -> 2601585 | I12: =SUM(I10:I11) -> 1186419 | J12: =SUM(J10:J11) -> 893795
B13: Altre attività operative immobilizzate
B14: Crediti diversi | C14: =SUMIF(case!$L:$L,$B14,case!B:B) -> 0 | D14: =SUMIF(case!$L:$L,$B14,case!C:C) -> 0 | E14: =SUMIF(case!$L:$L,$B14,case!D:D) -> 0 | F14: =SUMIF(case!$L:$L,$B14,case!E:E) -> 0 | G14: =SUMIF(case!$L:$L,$B14,case!F:F) -> 8192 | H14: =SUMIF(case!$L:$L,$B14,case!G:G) -> 8192 | I14: =SUMIF(case!$L:$L,$B14,case!H:H) -> 8192 | J14: =SUMIF(case!$L:$L,$B14,case!I:I) -> 8192
B15: Totale altre attività operative immobilizzate | C15: =SUM(C14) -> 0 | D15: =SUM(D14) -> 0 | E15: =SUM(E14) -> 0 | F15: =SUM(F14) -> 0 | G15: =SUM(G14) -> 8192 | H15: =SUM(H14) -> 8192 | I15: =SUM(I14) -> 8192 | J15: =SUM(J14) -> 8192
B16: Totale attività operative | C16: =C8+C12+C15 -> 18466453 | D16: =D8+D12+D15 -> 19461152 | E16: =E8+E12+E15 -> 18801163 | F16: =F8+F12+F15 -> 15728966 | G16: =G8+G12+G15 -> 12515168 | H16: =H8+H12+H15 -> 8525166 | I16: =I8+I12+I15 -> 6053487 | J16: =J8+J12+J15 -> 5427679
B18: Attività fiscali
B19: Crediti fisco-previdenziali | C19: =SUMIF(case!$L:$L,$B19,case!B:B) -> 23274 | D19: =SUMIF(case!$L:$L,$B19,case!C:C) -> 142981 | E19: =SUMIF(case!$L:$L,$B19,case!D:D) -> 705663 | F19: =SUMIF(case!$L:$L,$B19,case!E:E) -> 147272 | G19: =SUMIF(case!$L:$L,$B19,case!F:F) -> 284700 | H19: =SUMIF(case!$L:$L,$B19,case!G:G) -> 175791 | I19: =SUMIF(case!$L:$L,$B19,case!H:H) -> 57954 | J19: =SUMIF(case!$L:$L,$B19,case!I:I) -> 4758
B20: Attività per imposte anticipate | C20: =SUMIF(case!$L:$L,$B20,case!B:B) -> 0 | D20: =SUMIF(case!$L:$L,$B20,case!C:C) -> 0 | E20: =SUMIF(case!$L:$L,$B20,case!D:D) -> 0 | F20: =SUMIF(case!$L:$L,$B20,case!E:E) -> 0 | G20: =SUMIF(case!$L:$L,$B20,case!F:F) -> 0 | H20: =SUMIF(case!$L:$L,$B20,case!G:G) -> 0 | I20: =SUMIF(case!$L:$L,$B20,case!H:H) -> 0 | J20: =SUMIF(case!$L:$L,$B20,case!I:I) -> 0
B21: Totale attività fiscali | C21: =SUM(C19:C20) -> 23274 | D21: =SUM(D19:D20) -> 142981 | E21: =SUM(E19:E20) -> 705663 | F21: =SUM(F19:F20) -> 147272 | G21: =SUM(G19:G20) -> 284700 | H21: =SUM(H19:H20) -> 175791 | I21: =SUM(I19:I20) -> 57954 | J21: =SUM(J19:J20) -> 4758
B23: Attività accessorie
B24: Immobilizzazioni extra-operative | C24: =SUMIF(case!$L:$L,$B24,case!B:B) -> 0 | D24: =SUMIF(case!$L:$L,$B24,case!C:C) -> 0 | E24: =SUMIF(case!$L:$L,$B24,case!D:D) -> 0 | F24: =SUMIF(case!$L:$L,$B24,case!E:E) -> 0 | G24: =SUMIF(case!$L:$L,$B24,case!F:F) -> 0 | H24: =SUMIF(case!$L:$L,$B24,case!G:G) -> 0 | I24: =SUMIF(case!$L:$L,$B24,case!H:H) -> 0 | J24: =SUMIF(case!$L:$L,$B24,case!I:I) -> 0
B25: Partecipazioni | C25: =SUMIF(case!$L:$L,$B25,case!B:B) -> 58702 | D25: =SUMIF(case!$L:$L,$B25,case!C:C) -> 58702 | E25: =SUMIF(case!$L:$L,$B25,case!D:D) -> 58702 | F25: =SUMIF(case!$L:$L,$B25,case!E:E) -> 58702 | G25: =SUMIF(case!$L:$L,$B25,case!F:F) -> 6512 | H25: =SUMIF(case!$L:$L,$B25,case!G:G) -> 6512 | I25: =SUMIF(case!$L:$L,$B25,case!H:H) -> 6512 | J25: =SUMIF(case!$L:$L,$B25,case!I:I) -> 6512
B26: Crediti vs controllate e collegate | C26: =SUMIF(case!$L:$L,$B26,case!B:B) -> 0 | D26: =SUMIF(case!$L:$L,$B26,case!C:C) -> 0 | E26: =SUMIF(case!$L:$L,$B26,case!D:D) -> 0 | F26: =SUMIF(case!$L:$L,$B26,case!E:E) -> 0 | G26: =SUMIF(case!$L:$L,$B26,case!F:F) -> 0 | H26: =SUMIF(case!$L:$L,$B26,case!G:G) -> 0 | I26: =SUMIF(case!$L:$L,$B26,case!H:H) -> 0 | J26: =SUMIF(case!$L:$L,$B26,case!I:I) -> 0
B27: Totale attività accessorie | C27: =SUM(C24:C26) -> 58702 | D27: =SUM(D24:D26) -> 58702 | E27: =SUM(E24:E26) -> 58702 | F27: =SUM(F24:F26) -> 58702 | G27: =SUM(G24:G26) -> 6512 | H27: =SUM(H24:H26) -> 6512 | I27: =SUM(I24:I26) -> 6512 | J27: =SUM(J24:J26) -> 6512
B29: Attività finanziarie
B30: Riserve strategiche di liquidità | C30: =SUMIF(case!$L:$L,$B30,case!B:B) -> 0 | D30: =SUMIF(case!$L:$L,$B30,case!C:C) -> 0 | E30: =SUMIF(case!$L:$L,$B30,case!D:D) -> 0 | F30: =SUMIF(case!$L:$L,$B30,case!E:E) -> 0 | G30: =SUMIF(case!$L:$L,$B30,case!F:F) -> 0 | H30: =SUMIF(case!$L:$L,$B30,case!G:G) -> 0 | I30: =SUMIF(case!$L:$L,$B30,case!H:H) -> 0 | J30: =SUMIF(case!$L:$L,$B30,case!I:I) -> 0
B31: Attività di tesoreria | C31: =SUMIF(case!$L:$L,$B31,case!B:B) -> 242430 | D31: =SUMIF(case!$L:$L,$B31,case!C:C) -> 891542 | E31: =SUMIF(case!$L:$L,$B31,case!D:D) -> 1157532 | F31: =SUMIF(case!$L:$L,$B31,case!E:E) -> 2269671 | G31: =SUMIF(case!$L:$L,$B31,case!F:F) -> 1988631 | H31: =SUMIF(case!$L:$L,$B31,case!G:G) -> 603929 | I31: =SUMIF(case!$L:$L,$B31,case!H:H) -> 337078 | J31: =SUMIF(case!$L:$L,$B31,case!I:I) -> 712788
B32: Strumenti derivati attivi | C32: =SUMIF(case!$L:$L,$B32,case!B:B) -> 0 | D32: =SUMIF(case!$L:$L,$B32,case!C:C) -> 0 | E32: =SUMIF(case!$L:$L,$B32,case!D:D) -> 0 | F32: =SUMIF(case!$L:$L,$B32,case!E:E) -> 0 | G32: =SUMIF(case!$L:$L,$B32,case!F:F) -> 0 | H32: =SUMIF(case!$L:$L,$B32,case!G:G) -> 0 | I32: =SUMIF(case!$L:$L,$B32,case!H:H) -> 0 | J32: =SUMIF(case!$L:$L,$B32,case!I:I) -> 0
B33: Totale attività finanziarie | C33: =SUM(C30:C32) -> 242430 | D33: =SUM(D30:D32) -> 891542 | E33: =SUM(E30:E32) -> 1157532 | F33: =SUM(F30:F32) -> 2269671 | G33: =SUM(G30:G32) -> 1988631 | H33: =SUM(H30:H32) -> 603929 | I33: =SUM(I30:I32) -> 337078 | J33: =SUM(J30:J32) -> 712788
B35: Totale attivo | C35: =C16+C21+C27+C33 -> 18790859 | D35: =D16+D21+D27+D33 -> 20554377 | E35: =E16+E21+E27+E33 -> 20723060 | F35: =F16+F21+F27+F33 -> 18204611 | G35: =G16+G21+G27+G33 -> 14795011 | H35: =H16+H21+H27+H33 -> 9311398 | I35: =I16+I21+I27+I33 -> 6455031 | J35: =J16+J21+J27+J33 -> 6151737
B37: Check con totale attivo AIDA | C37: =case!B95 -> 18790859 | D37: =case!C95 -> 20554377 | E37: =case!D95 -> 20723060 | F37: =case!E95 -> 18204611 | G37: =case!F95 -> 14795011 | H37: =case!G95 -> 9311398 | I37: =case!H95 -> 6455031 | J37: =case!I95 -> 6151737
B38: Differenza tra totale attivo e totale attivo AIDA | C38: =C37-C35 -> 0 | D38: =D37-D35 -> 0 | E38: =E37-E35 -> 0 | F38: =F37-F35 -> 0 | G38: =G37-G35 -> 0 | H38: =H37-H35 -> 0 | I38: =I37-I35 -> 0 | J38: =J37-J35 -> 0
B39: Somma voci spostate nel passivo | C39: =case!B2+case!B46 -> 0 | D39: =case!C2+case!C46 -> 0 | E39: =case!D2+case!D46 -> 0 | F39: =case!E2+case!E46 -> 0 | G39: =case!F2+case!F46 -> 0 | H39: =case!G2+case!G46 -> 0 | I39: =case!H2+case!H46 -> 0 | J39: =case!I2+case!I46 -> 0
B40: Sbilancio | C40: =C38+C39 -> 0 | D40: =D38+D39 -> 0 | E40: =E38+E39 -> 0 | F40: =F38+F39 -> 0 | G40: =G38+G39 -> 0 | H40: =H38+H39 -> 0 | I40: =I38+I39 -> 0 | J40: =J38+J39 -> 0
B45: Stato Patrimoniale Passivo | C45: =C2 -> 31/12/2024 | D45: =D2 -> 31/12/2023 | E45: =E2 -> 31/12/2022 | F45: =F2 -> 31/12/2021 | G45: =G2 -> 31/12/2020 | H45: =H2 -> 31/12/2019 | I45: =I2 -> 31/12/2018 | J45: =J2 -> 31/12/2017
B46: Passività operative
B47: Passività operative correnti | C47: =SUMIF(case!$L:$L,$B47,case!B:B) -> 0 | D47: =SUMIF(case!$L:$L,$B47,case!C:C) -> 0 | E47: =SUMIF(case!$L:$L,$B47,case!D:D) -> 0 | F47: =SUMIF(case!$L:$L,$B47,case!E:E) -> 0 | G47: =SUMIF(case!$L:$L,$B47,case!F:F) -> 0 | H47: =SUMIF(case!$L:$L,$B47,case!G:G) -> 0 | I47: =SUMIF(case!$L:$L,$B47,case!H:H) -> 0 | J47: =SUMIF(case!$L:$L,$B47,case!I:I) -> 0
B48: Debiti vs fornitori | C48: =SUMIF(case!$L:$L,$B48,case!B:B) -> 2274193 | D48: =SUMIF(case!$L:$L,$B48,case!C:C) -> 2343088 | E48: =SUMIF(case!$L:$L,$B48,case!D:D) -> 2517619 | F48: =SUMIF(case!$L:$L,$B48,case!E:E) -> 2142223 | G48: =SUMIF(case!$L:$L,$B48,case!F:F) -> 1385728 | H48: =SUMIF(case!$L:$L,$B48,case!G:G) -> 2083244 | I48: =SUMIF(case!$L:$L,$B48,case!H:H) -> 1195746 | J48: =SUMIF(case!$L:$L,$B48,case!I:I) -> 1264218
B49: Debiti vs dipendenti | C49: =SUMIF(case!$L:$L,$B49,case!B:B) -> 0 | D49: =SUMIF(case!$L:$L,$B49,case!C:C) -> 0 | E49: =SUMIF(case!$L:$L,$B49,case!D:D) -> 0 | F49: =SUMIF(case!$L:$L,$B49,case!E:E) -> 0 | G49: =SUMIF(case!$L:$L,$B49,case!F:F) -> 0 | H49: =SUMIF(case!$L:$L,$B49,case!G:G) -> 0 | I49: =SUMIF(case!$L:$L,$B49,case!H:H) -> 0 | J49: =SUMIF(case!$L:$L,$B49,case!I:I) -> 0
B50: Altre passività operative correnti | C50: =SUMIF(case!$L:$L,$B50,case!B:B) -> 1755910 | D50: =SUMIF(case!$L:$L,$B50,case!C:C) -> 1902846 | E50: =SUMIF(case!$L:$L,$B50,case!D:D) -> 1988017 | F50: =SUMIF(case!$L:$L,$B50,case!E:E) -> 743242 | G50: =SUMIF(case!$L:$L,$B50,case!F:F) -> 648237 | H50: =SUMIF(case!$L:$L,$B50,case!G:G) -> 547878 | I50: =SUMIF(case!$L:$L,$B50,case!H:H) -> 447728 | J50: =SUMIF(case!$L:$L,$B50,case!I:I) -> 399886
...

Sheet RF
B1: Rendiconto finanziario | C1: =case!B1 -> 31/12/2024 | D1: =case!C1 -> 31/12/2023 | E1: =case!D1 -> 31/12/2022 | F1: =case!E1 -> 31/12/2021 | G1: =case!F1 -> 31/12/2020 | H1: =case!G1 -> 31/12/2019 | I1: =case!H1 -> 31/12/2018 | J1: =case!I1 -> 31/12/2017
B2: Flussi di cassa della gestione operativa e accessoria
B3: Flussi di cassa della gestione operativa corrente
A4: + | B4: Reddito operativo | C4: ='RC'!C131 -> 1588849 | D4: ='RC'!D131 -> 1117327 | E4: ='RC'!E131 -> 963975 | F4: ='RC'!F131 -> 1411257 | G4: ='RC'!G131 -> 1351726 | H4: ='RC'!H131 -> 1069627 | I4: ='RC'!I131 -> 1052950 | J4: ='RC'!J131 -> 635847
A5: ± | B5: Reddito gestioni accessoria e straordinaria | C5: ='RC'!C146 -> 0 | D5: ='RC'!D146 -> 0 | E5: ='RC'!E146 -> 0 | F5: ='RC'!F146 -> 0 | G5: ='RC'!G146 -> 0 | H5: ='RC'!H146 -> 0 | I5: ='RC'!I146 -> 0 | J5: ='RC'!J146 -> 0
A6: + | B6: Riaggiunta ammortamenti | C6: =-'RC'!C124 -> 916802 | D6: =-'RC'!D124 -> 899828 | E6: =-'RC'!E124 -> 856051 | F6: =-'RC'!F124 -> 470290 | G6: =-'RC'!G124 -> 171279 | H6: =-'RC'!H124 -> 180598 | I6: =-'RC'!I124 -> 184962 | J6: =-'RC'!J124 -> 215317
A7: - | B7: (Imposte + Risparmio fiscale interessi netti) | C7: =-('RC'!C149+'RC'!C157) -> 100967.94 | D7: =-('RC'!D149+'RC'!D157) -> 2676.0664 | E7: =-('RC'!E149+'RC'!E157) -> 20538.049 | F7: =-('RC'!F149+'RC'!F157) -> 201174.49 | G7: =-('RC'!G149+'RC'!G157) -> 235308.93 | H7: =-('RC'!H149+'RC'!H157) -> 196885.32 | I7: =-('RC'!I149+'RC'!I157) -> 250659.96 | J7: =-('RC'!J149+'RC'!J157) -> 136307.83
A8: = | B8: EBITDA al netto delle imposte | C8: =C4+C5+C6-C7 -> 2404683.1 | D8: =D4+D5+D6-D7 -> 2014478.9 | E8: =E4+E5+E6-E7 -> 1799488 | F8: =F4+F5+F6-F7 -> 1680372.5 | G8: =G4+G5+G6-G7 -> 1287696.1 | H8: =H4+H5+H6-H7 -> 1053339.7 | I8: =I4+I5+I6-I7 -> 987252.04 | J8: =J4+J5+J6-J7 -> 714856.17
B9: Rettifiche per determinare il flusso di cassa
B10: Variazione del CCON*
A11: - | B11: (Aumento) diminuzione crediti verso clienti | C11: =-'RC'!C5 -> -4256399 | D11: =-'RC'!D5 -> -3896776 | E11: =-'RC'!E5 -> -2966203 | F11: =-'RC'!F5 -> -3180616 | G11: =-'RC'!G5 -> -2787212 | H11: =-'RC'!H5 -> -2642901 | I11: =-'RC'!I5 -> -2353521 | J11: =-'RC'!J5 -> -2381302
A12: - | B12: (Aumento) diminuzione scorte magazzino | C12: =-'RC'!C6 -> -4608814 | D12: =-'RC'!D6 -> -5040346 | E12: =-'RC'!E6 -> -5250264 | F12: =-'RC'!F6 -> -2924371 | G12: =-'RC'!G6 -> -2556678 | H12: =-'RC'!H6 -> -3010721 | I12: =-'RC'!I6 -> -2422241 | J12: =-'RC'!J6 -> -2070635
A13: - | B13: (Aumento) diminuzione altre attività correnti | C13: =-'RC'!C7 -> -816992 | D13: =-'RC'!D7 -> -1399880 | E13: =-'RC'!E7 -> -1028451 | F13: =-'RC'!F7 -> -116979 | G13: =-'RC'!G7 -> -104609 | H13: =-'RC'!H7 -> -261767 | I13: =-'RC'!I7 -> -83114 | J13: =-'RC'!J7 -> -73755
A14: + | B14: Aumento (diminuzione) debiti verso fornitori | C14: ='RC'!C48 -> 2274193 | D14: ='RC'!D48 -> 2343088 | E14: ='RC'!E48 -> 2517619 | F14: ='RC'!F48 -> 2142223 | G14: ='RC'!G48 -> 1385728 | H14: ='RC'!H48 -> 2083244 | I14: ='RC'!I48 -> 1195746 | J14: ='RC'!J48 -> 1264218
A15: + | B15: Aumento (diminuzione) altre passività correnti | C15: ='RC'!C50 -> 1755910 | D15: ='RC'!D50 -> 1902846 | E15: ='RC'!E50 -> 1988017 | F15: ='RC'!F50 -> 743242 | G15: ='RC'!G50 -> 648237 | H15: ='RC'!H50 -> 547878 | I15: ='RC'!I50 -> 447728 | J15: ='RC'!J50 -> 399886
A16: - | B16: (Aumento) diminuzione attività fiscali | C16: =-'RC'!C21 -> -23274 | D16: =-'RC'!D21 -> -142981 | E16: =-'RC'!E21 -> -705663 | F16: =-'RC'!F21 -> -147272 | G16: =-'RC'!G21 -> -284700 | H16: =-'RC'!H21 -> -175791 | I16: =-'RC'!I21 -> -57954 | J16: =-'RC'!J21 -> -4758
A17: + | B17: Aumento (diminuzione) passività fiscali | C17: ='RC'!C62 -> 305861 | D17: ='RC'!D62 -> 221774 | E17: ='RC'!E62 -> 130071 | F17: ='RC'!F62 -> 171771 | G17: ='RC'!G62 -> 152360 | H17: ='RC'!H62 -> 109971 | I17: ='RC'!I62 -> 257456 | J17: ='RC'!J62 -> 344734
A18: = | B18: (Aumento) diminuzione CCON* | C18: =SUM(C11:C17) -> -5369515 | D18: =SUM(D11:D17) -> -6012275 | E18: =SUM(E11:E17) -> -5314874 | F18: =SUM(F11:F17) -> -3312002 | G18: =SUM(G11:G17) -> -3546874 | H18: =SUM(H11:H17) -> -3350087 | I18: =SUM(I11:I17) -> -3015900 | J18: =SUM(J11:J17) -> -2521612
A19: + | B19: Aumento (diminuzione) fondo TFR | C19: ='RC'!C53 -> 191675 | D19: ='RC'!D53 -> 179286 | E19: ='RC'!E53 -> 189098 | F19: ='RC'!F53 -> 197380 | G19: ='RC'!G53 -> 174392 | H19: ='RC'!H53 -> 206556 | I19: ='RC'!I53 -> 187238 | J19: ='RC'!J53 -> 173667
A20: - | B20: (Aumento) diminuzione altre attività operative immobilizzate | C20: =-'RC'!C15 -> 0 | D20: =-'RC'!D15 -> 0 | E20: =-'RC'!E15 -> 0 | F20: =-'RC'!F15 -> 0 | G20: =-'RC'!G15 -> -8192 | H20: =-'RC'!H15 -> -8192 | I20: =-'RC'!I15 -> -8192 | J20: =-'RC'!J15 -> -8192
A21: + | B21: Aumento (diminuzione) altre passività operative consolidate | C21: ='RC'!C54 -> 0 | D21: ='RC'!D54 -> 0 | E21: ='RC'!E54 -> 0 | F21: ='RC'!F54 -> 0 | G21: ='RC'!G54 -> 0 | H21: ='RC'!H54 -> 0 | I21: ='RC'!I54 -> 0 | J21: ='RC'!J54 -> 0
A22: = | B22: Totale rettifiche | C22: =SUM(C18:C21) -> -5177840 | D22: =SUM(D18:D21) -> -5832989 | E22: =SUM(E18:E21) -> -5125776 | F22: =SUM(F18:F21) -> -3114622 | G22: =SUM(G18:G21) -> -3380674 | H22: =SUM(H18:H21) -> -3151723 | I22: =SUM(I18:I21) -> -2836854 | J22: =SUM(J18:J21) -> -2356137
A23: = | B23: Flussi di cassa netti gestione operativa corrente, acc e straord. | C23: =C8+C22 -> -2773156.9 | D23: =D8+D22 -> -3818510.1 | E23: =E8+E22 -> -3326288 | F23: =F8+F22 -> -1434249.5 | G23: =G8+G22 -> -2092977.9 | H23: =H8+H22 -> -2098383.3 | I23: =I8+I22 -> -1849602 | J23: =J8+J22 -> -1641280.8
B24: Flussi di cassa della gestione investimenti | N24: 31/12/2021 | O24: 31/12/2022 | P24: 31/12/2023 | Q24: 31/12/2024
A25: - | B25: (Aumento) diminuzione Immobilizzazioni operative nette | C25: =-'RC'!C12 -> -8784248 | D25: =-'RC'!D12 -> -9124150 | E25: =-'RC'!E12 -> -9556245 | F25: =-'RC'!F12 -> -9507000 | G25: =-'RC'!G12 -> -7058477 | H25: =-'RC'!H12 -> -2601585 | I25: =-'RC'!I12 -> -1186419 | J25: =-'RC'!J12 -> -893795 | M25: FCFF | N25: =F31-G31 -> -2140995.6 | O25: =E31-F31 -> -2327044.6 | P25: =D31-E31 -> -103904.02 | Q25: =C31-D31 -> 1368281.1
A26: - | B26: (Aumento) diminuzione attività accessorie | C26: =-'RC'!C27 -> -58702 | D26: =-'RC'!D27 -> -58702 | E26: =-'RC'!E27 -> -58702 | F26: =-'RC'!F27 -> -58702 | G26: =-'RC'!G27 -> -6512 | H26: =-'RC'!H27 -> -6512 | I26: =-'RC'!I27 -> -6512 | J26: =-'RC'!J27 -> -6512 | M26: FCFE | N26: =F41-G41 -> -555241 | O26: =E41-F41 -> -1973445 | P26: =D41-E41 -> -944569 | Q26: =C41-D41 -> -845781
A27: + | B27: Aumento (diminuzione) debiti vs controllate e collegate | C27: ='RC'!C66 -> 0 | D27: ='RC'!D66 -> 0 | E27: ='RC'!E66 -> 0 | F27: ='RC'!F66 -> 0 | G27: ='RC'!G66 -> 0 | H27: ='RC'!H66 -> 0 | I27: ='RC'!I66 -> 0 | J27: ='RC'!J66 -> 0 | M27: FCCP | N27: =F48-G48 -> 836281 | O27: =E48-F48 -> 861306 | P27: =D48-E48 -> 678579 | Q27: =C48-D48 -> 196669
A28: - | B28: (Ammortamenti) | C28: ='RC'!C124 -> -916802 | D28: ='RC'!D124 -> -899828 | E28: ='RC'!E124 -> -856051 | F28: ='RC'!F124 -> -470290 | G28: ='RC'!G124 -> -171279 | H28: ='RC'!H124 -> -180598 | I28: ='RC'!I124 -> -184962 | J28: ='RC'!J124 -> -215317 | M28: NCF | N28: =N26+N27 -> 281040 | O28: =O27+O26 -> -1112139 | P28: =P26+P27 -> -265990 | Q28: =Q26+Q27 -> -649112
A29: + | B29: Aumento (diminuzione) riserve da rivalutazione | C29: ='RC'!C80 -> 0 | D29: ='RC'!D80 -> 0 | E29: ='RC'!E80 -> 0 | F29: ='RC'!F80 -> 0 | G29: ='RC'!G80 -> 0 | H29: ='RC'!H80 -> 0 | I29: ='RC'!I80 -> 0 | J29: ='RC'!J80 -> 0
A30: = | B30: Flussi di cassa netti della gestione investimenti | C30: =SUM(C25:C29) -> -9759752 | D30: =SUM(D25:D29) -> -10082680 | E30: =SUM(E25:E29) -> -10470998 | F30: =SUM(F25:F29) -> -10035992 | G30: =SUM(G25:G29) -> -7236268 | H30: =SUM(H25:H29) -> -2788695 | I30: =SUM(I25:I29) -> -1377893 | J30: =SUM(J25:J29) -> -1115624
A31: = | B31: Free cash flow to the firm (FCFF) | C31: =C23+C30 -> -12532909 | D31: =D23+D30 -> -13901190 | E31: =E23+E30 -> -13797286 | F31: =F23+F30 -> -11470241 | G31: =G23+G30 -> -9329245.9 | H31: =H23+H30 -> -4887078.3 | I31: =I23+I30 -> -3227495 | J31: =J23+J30 -> -2756904.8
B32: Flussi di cassa della gestione finanziaria
B33: Debito e attività finanziarie (esclusa tesoreria)
A34: - | B34: (Oneri finanziari netti) | C34: ='RC'!C140 -> -501648 | D34: ='RC'!D140 -> -526256 | E34: ='RC'!E140 -> -253466 | F34: ='RC'!F140 -> -207017 | G34: ='RC'!G140 -> -158955 | H34: ='RC'!H140 -> -98799 | I34: ='RC'!I140 -> -101816 | J34: ='RC'!J140 -> -102408
A35: + | B35: Risparmio fiscale interessi netti | C35: =-'RC'!C157 -> -86500.056 | D35: =-'RC'!D157 -> -21727.934 | E35: =-'RC'!E157 -> -11389.951 | F35: =-'RC'!F157 -> -41762.513 | G35: =-'RC'!G157 -> -36180.066 | H35: =-'RC'!H157 -> -22306.681 | I35: =-'RC'!I157 -> -30049.044 | J35: =-'RC'!J157 -> -32385.17
A36: + | B36: Strumenti derivati: (aumento) diminuzione attivi + aumento (diminuzione) passivi | C36: =-'RC'!C32+'RC'!C72 -> 0 | D36: =-'RC'!D32+'RC'!D72 -> 0 | E36: =-'RC'!E32+'RC'!E72 -> 0 | F36: =-'RC'!F32+'RC'!F72 -> 0 | G36: =-'RC'!G32+'RC'!G72 -> 0 | H36: =-'RC'!H32+'RC'!H72 -> 0 | I36: =-'RC'!I32+'RC'!I72 -> 0 | J36: =-'RC'!J32+'RC'!J72 -> 0
A37: + | B37: Aumento (diminuzione) debiti struttturali a medio-lungo | C37: ='RC'!C69 -> 5110204 | D37: ='RC'!D69 -> 6691873 | E37: ='RC'!E69 -> 6717513 | F37: ='RC'!F69 -> 7372195 | G37: ='RC'!G69 -> 6304053 | H37: ='RC'!H69 -> 588287 | I37: ='RC'!I69 -> 808395 | J37: ='RC'!J69 -> 952264
A38: + | B38: Aumento (diminuzione) debiti strutturali a breve | C38: ='RC'!C70 -> 3395729 | D38: ='RC'!D70 -> 3987958 | E38: ='RC'!E70 -> 4519855 | F38: ='RC'!F70 -> 3495497 | G38: ='RC'!G70 -> 2924240 | H38: ='RC'!H70 -> 3390744 | I38: ='RC'!I70 -> 1825387 | J38: ='RC'!J70 -> 1954310
A39: - | B39: (Aumento) diminuzione riserve strategiche di liquidità | C39: =-'RC'!C30 -> 0 | D39: =-'RC'!D30 -> 0 | E39: =-'RC'!E30 -> 0 | F39: =-'RC'!F30 -> 0 | G39: =-'RC'!G30 -> 0 | H39: =-'RC'!H30 -> 0 | I39: =-'RC'!I30 -> 0 | J39: =-'RC'!J30 -> 0
A40: = | B40: Flussi di cassa netti sul debito netto (esclusa tesoreria) (FCDN) | C40: =SUM(C34:C39) -> 7917784.9 | D40: =SUM(D34:D39) -> 10131847 | E40: =SUM(E34:E39) -> 10972512 | F40: =SUM(F34:F39) -> 10618912 | G40: =SUM(G34:G39) -> 9033157.9 | H40: =SUM(H34:H39) -> 3857925.3 | I40: =SUM(I34:I39) -> 2501917 | J40: =SUM(J34:J39) -> 2771780.8
...

Sheet ind
A1: INDICATORI FINANZIARI | B1: =RF!C1 -> 31/12/2024 | C1: =RF!D1 -> 31/12/2023 | D1: =RF!E1 -> 31/12/2022 | E1: =RF!F1 -> 31/12/2021 | F1: =RF!G1 -> 31/12/2020 | G1: =RF!H1 -> 31/12/2019 | H1: =RF!I1 -> 31/12/2018 | I1: =RF!J1 -> 31/12/2017
A2: valori patrimoniali medie t-1 per attenuare variazioni significativi
A3: RLA (redd. gest OFA) | B3: ='RC'!C131+'RC'!C140+'RC'!C144 -> 1087201 | C3: ='RC'!D131+'RC'!D140+'RC'!D144 -> 591071 | D3: ='RC'!E131+'RC'!E140+'RC'!E144 -> 710509 | E3: ='RC'!F131+'RC'!F140+'RC'!F144 -> 1204240 | F3: ='RC'!G131+'RC'!G140+'RC'!G144 -> 1192771 | G3: ='RC'!H131+'RC'!H140+'RC'!H144 -> 970828 | H3: ='RC'!I131+'RC'!I140+'RC'!I144 -> 951134 | I3: ='RC'!J131+'RC'!J140+'RC'!J144 -> 533439
A4: Reddito operativo | B4: ='RC'!C131 -> 1588849 | C4: ='RC'!D131 -> 1117327 | D4: ='RC'!E131 -> 963975 | E4: ='RC'!F131 -> 1411257 | F4: ='RC'!G131 -> 1351726 | G4: ='RC'!H131 -> 1069627 | H4: ='RC'!I131 -> 1052950 | I4: ='RC'!J131 -> 635847
A5: EBITDA(MOL) | B5: ='RC'!C123 -> 2481804 | C5: ='RC'!D123 -> 1835259 | D5: ='RC'!E123 -> 1706003 | E5: ='RC'!F123 -> 1926582 | F5: ='RC'!G123 -> 1540277 | G5: ='RC'!H123 -> 1357618 | H5: ='RC'!I123 -> 1405132 | I5: ='RC'!J123 -> 1124651
A6: Reddito netto | B6: ='RC'!C150 -> 899733 | C6: ='RC'!D150 -> 566667 | D6: ='RC'!E150 -> 678581 | E6: ='RC'!F150 -> 961303 | F6: ='RC'!G150 -> 921282 | G6: ='RC'!H150 -> 751636 | H6: ='RC'!I150 -> 670425 | I6: ='RC'!J150 -> 364746
A7: Ricavi | B7: ='RC'!C111 -> 21650995 | C7: ='RC'!D111 -> 21142391 | D7: ='RC'!E111 -> 17821289 | E7: ='RC'!F111 -> 15638358 | F7: ='RC'!G111 -> 14336879 | G7: ='RC'!H111 -> 13550152 | H7: ='RC'!I111 -> 11519434 | I7: ='RC'!J111 -> 9917341
A8: Ricavi t-1 | B8: ='RC'!D111 -> 21142391 | C8: ='RC'!E111 -> 17821289 | D8: ='RC'!F111 -> 15638358 | E8: ='RC'!G111 -> 14336879 | F8: ='RC'!H111 -> 13550152 | G8: ='RC'!I111 -> 11519434 | H8: ='RC'!J111 -> 9917341 | I8: ='RC'!#REF! -> #ERROR!
A9: Ricavi con IVA gg | B9: =B7*1.22/365 -> 72367.709 | C9: =C7*1.22/365 -> 70667.718 | D9: =D7*1.22/365 -> 59567.048 | E9: =E7*1.22/365 -> 52270.676 | F9: =F7*1.22/365 -> 47920.527 | G9: =G7*1.22/365 -> 45290.919 | H9: =H7*1.22/365 -> 38503.314 | I9: =I7*1.22/365 -> 33148.373
A10: Acquisti | B10: ='RC'!C116 -> -17239201 | C10: ='RC'!D116 -> -17541147 | D10: ='RC'!E116 -> -16838729 | E10: ='RC'!F116 -> -12600246 | F10: ='RC'!G116 -> -11051119 | G10: ='RC'!H116 -> -11504899 | H10: ='RC'!I116 -> -9369872 | I10: ='RC'!J116 -> -7915457
A11: Acquisti con IVA gg | B11: ='RC'!C116*1.22/365 -> -57621.439 | C11: ='RC'!D116*1.22/365 -> -58630.683 | D11: ='RC'!E116*1.22/365 -> -56282.875 | E11: ='RC'!F116*1.22/365 -> -42115.891 | F11: ='RC'!G116*1.22/365 -> -36937.987 | G11: ='RC'!H116*1.22/365 -> -38454.731 | H11: ='RC'!I116*1.22/365 -> -31318.476 | I11: ='RC'!J116*1.22/365 -> -26457.144
A12: Costo del venduto gg medio | B12: =AVERAGE('RC'!C120:D120)/365 -> -48523.011 | C12: =AVERAGE('RC'!D120:E120)/365 -> -44197.125 | D12: =AVERAGE('RC'!E120:F120)/365 -> -36637.518 | E12: =AVERAGE('RC'!F120:G120)/365 -> -32517.418 | F12: =AVERAGE('RC'!G120:H120)/365 -> -30714.495 | G12: =AVERAGE('RC'!H120:I120)/365 -> -27307.786 | H12: =AVERAGE('RC'!I120:J120)/365 -> -23215.595 | I12: =AVERAGE('RC'!J120)/365 -> -21723.611
A13: Costo del personale gg medio | B13: =AVERAGE('RC'!C122:D122)/365 -> -4184.2808 | C13: =AVERAGE('RC'!D122:E122)/365 -> -4326.7356 | D13: =AVERAGE('RC'!E122:F122)/365 -> -4221.4712 | E13: =AVERAGE('RC'!F122:G122)/365 -> -3795.4288 | F13: =AVERAGE('RC'!G122:H122)/365 -> -3517.1986 | G13: =AVERAGE('RC'!H122:I122)/365 -> -3249.5233 | H13: =AVERAGE('RC'!I122:J122)/365 -> -2684.3945 | I13: =AVERAGE('RC'!J122)/365 -> -2365.9507
A14: AON* medio | B14: =AVERAGE('RC'!C93,'RC'!D93) -> 14459614 | C14: =AVERAGE('RC'!D93,'RC'!E93) -> 14819580 | D14: =AVERAGE('RC'!E93,'RC'!F93) -> 13651822 | E14: =AVERAGE('RC'!F93,'RC'!G93) -> 11530386 | F14: =AVERAGE('RC'!G93,'RC'!H93) -> 8096229.5 | G14: =AVERAGE('RC'!H93,'RC'!I93) -> 4888290.5 | H14: =AVERAGE('RC'!I93,'RC'!J93) -> 3636602.5 | I14: =AVERAGE('RC'!I93,'RC'!#REF!) -> #ERROR!
A15: AON* init | B15: ='RC'!D93 -> 14957139 | C15: ='RC'!E93 -> 14682021 | D15: ='RC'!F93 -> 12621622 | E15: ='RC'!G93 -> 10439151 | F15: ='RC'!H93 -> 5753308 | G15: ='RC'!I93 -> 4023273 | H15: ='RC'!J93 -> 3249932 | I15: ='RC'!#REF! -> #ERROR!
A16: AON* fin | B16: ='RC'!C93 -> 13962088 | C16: ='RC'!D93 -> 14957139 | D16: ='RC'!E93 -> 14682021 | E16: ='RC'!F93 -> 12621622 | F16: ='RC'!G93 -> 10439151 | G16: ='RC'!H93 -> 5753308 | H16: ='RC'!I93 -> 4023273 | I16: ='RC'!J93 -> 3249932
A17: Reddito att.acc (prov-oneri acc) | B17: ='RC'!C144 -> 0 | C17: ='RC'!D144 -> 0 | D17: ='RC'!E144 -> 0 | E17: ='RC'!F144 -> 0 | F17: ='RC'!G144 -> 0 | G17: ='RC'!H144 -> 0 | H17: ='RC'!I144 -> 0 | I17: ='RC'!J144 -> 0
A18: AACCN media(ris gest acc) | B18: =AVERAGE('RC'!C94,'RC'!D94) -> 58702 | C18: =AVERAGE('RC'!D94,'RC'!E94) -> 58702 | D18: =AVERAGE('RC'!E94,'RC'!F94) -> 58702 | E18: =AVERAGE('RC'!F94,'RC'!G94) -> 32607 | F18: =AVERAGE('RC'!G94,'RC'!H94) -> 6512 | G18: =AVERAGE('RC'!H94,'RC'!I94) -> 6512 | H18: =AVERAGE('RC'!I94,'RC'!J94) -> 6512 | I18: =AVERAGE('RC'!I94,'RC'!#REF!) -> #ERROR!
A19: AACC medie(solo attività) | B19: =AVERAGE('RC'!C27,'RC'!D27) -> 58702 | C19: =AVERAGE('RC'!D27,'RC'!E27) -> 58702 | D19: =AVERAGE('RC'!E27,'RC'!F27) -> 58702 | E19: =AVERAGE('RC'!F27,'RC'!G27) -> 32607 | F19: =AVERAGE('RC'!G27,'RC'!H27) -> 6512 | G19: =AVERAGE('RC'!H27,'RC'!I27) -> 6512 | H19: =AVERAGE('RC'!I27,'RC'!J27) -> 6512 | I19: =AVERAGE('RC'!I27,'RC'!#REF!) -> #ERROR!
A20: AACC finali | B20: ='RC'!C27 -> 58702 | C20: ='RC'!D27 -> 58702 | D20: ='RC'!E27 -> 58702 | E20: ='RC'!F27 -> 58702 | F20: ='RC'!G27 -> 6512 | G20: ='RC'!H27 -> 6512 | H20: ='RC'!I27 -> 6512 | I20: ='RC'!J27 -> 6512
A21: PACC medie (solo passivo) | B21: =AVERAGE('RC'!C66,'RC'!D66) -> 0 | C21: =AVERAGE('RC'!D66,'RC'!E66) -> 0 | D21: =AVERAGE('RC'!E66,'RC'!F66) -> 0 | E21: =AVERAGE('RC'!F66,'RC'!G66) -> 0 | F21: =AVERAGE('RC'!G66,'RC'!H66) -> 0 | G21: =AVERAGE('RC'!H66,'RC'!I66) -> 0 | H21: =AVERAGE('RC'!I66,'RC'!J66) -> 0 | I21: =AVERAGE('RC'!I66,'RC'!#REF!) -> #ERROR!
A22: PACC finali (solo passivo) | B22: ='RC'!C66 -> 0 | C22: ='RC'!D66 -> 0 | D22: ='RC'!E66 -> 0 | E22: ='RC'!F66 -> 0 | F22: ='RC'!G66 -> 0 | G22: ='RC'!H66 -> 0 | H22: ='RC'!I66 -> 0 | I22: ='RC'!J66 -> 0
A23: ris gest str | B23: ='RC'!C145 -> 0 | C23: ='RC'!D145 -> 0 | D23: ='RC'!E145 -> 0 | E23: ='RC'!F145 -> 0 | F23: ='RC'!G145 -> 0 | G23: ='RC'!H145 -> 0 | H23: ='RC'!I145 -> 0 | I23: ='RC'!J145 -> 0
A24: PFN (ris gest fin) | B24: =B30-B31 -> 9025896 | C24: =C30-C31 -> 9934062.5 | D24: =D30-D31 -> 9338928.5 | E24: =E30-E31 -> 7918841.5 | F24: =F30-F31 -> 5307382 | G24: =G30-G31 -> 2835903 | H24: =H30-H31 -> 2245245 | I24: =I30-I31 -> #ERROR!
A25: DEBn | B25: =IF(B24>0, B24, 0) -> 9025896 | C25: =IF(C24>0, C24, 0) -> 9934062.5 | D25: =IF(D24>0, D24, 0) -> 9338928.5 | E25: =IF(E24>0, E24, 0) -> 7918841.5 | F25: =IF(F24>0, F24, 0) -> 5307382 | G25: =IF(G24>0, G24, 0) -> 2835903 | H25: =IF(H24>0, H24, 0) -> 2245245 | I25: =IF(I24>0, I24, 0) -> #ERROR!
A26: LIQn | B26: =IF(B24<0, -B24, 0) -> 0 | C26: =IF(C24<0, C24, 0) -> 0 | D26: =IF(D24<0, D24, 0) -> 0 | E26: =IF(E24<0, E24, 0) -> 0 | F26: =IF(F24<0, F24, 0) -> 0 | G26: =IF(G24<0, G24, 0) -> 0 | H26: =IF(H24<0, H24, 0) -> 0 | I26: =IF(I24<0, I24, 0) -> #ERROR!
A27: oneri finanziari | B27: ='RC'!C138 -> -503404 | C27: ='RC'!D138 -> -528343 | D27: ='RC'!E138 -> -253674 | E27: ='RC'!F138 -> -207408 | F27: ='RC'!G138 -> -159160 | G27: ='RC'!H138 -> -102930 | H27: ='RC'!I138 -> -102001 | I27: ='RC'!J138 -> -102507
A28: interessi attivi | B28: ='RC'!C137 -> 1756 | C28: ='RC'!D137 -> 2087 | D28: ='RC'!E137 -> 208 | E28: ='RC'!F137 -> 391 | F28: ='RC'!G137 -> 205 | G28: ='RC'!H137 -> 4131 | H28: ='RC'!I137 -> 185 | I28: ='RC'!J137 -> 99
A29: imposta | B29: ='RC'!C149 -> -187468 | C29: ='RC'!D149 -> -24404 | D29: ='RC'!E149 -> -31928 | E29: ='RC'!F149 -> -242937 | F29: ='RC'!G149 -> -271489 | G29: ='RC'!H149 -> -219192 | H29: ='RC'!I149 -> -280709 | I29: ='RC'!J149 -> -168693
A30: Debito lordo medio(pass. gest. fin) | B30: =AVERAGE('RC'!C73,'RC'!D73) -> 9592882 | C30: =AVERAGE('RC'!D73,'RC'!E73) -> 10958600 | D30: =AVERAGE('RC'!E73,'RC'!F73) -> 11052530 | E30: =AVERAGE('RC'!F73,'RC'!G73) -> 10047992 | F30: =AVERAGE('RC'!G73,'RC'!H73) -> 6603662 | G30: =AVERAGE('RC'!H73,'RC'!I73) -> 3306406.5 | H30: =AVERAGE('RC'!I73,'RC'!J73) -> 2770178 | I30: =AVERAGE('RC'!I73,'RC'!#REF!) -> #ERROR!
A31: Liq. lorda media(att. gest fin) | B31: =AVERAGE('RC'!C33,'RC'!D33) -> 566986 | C31: =AVERAGE('RC'!D33,'RC'!E33) -> 1024537 | D31: =AVERAGE('RC'!E33,'RC'!F33) -> 1713601.5 | E31: =AVERAGE('RC'!F33,'RC'!G33) -> 2129151 | F31: =AVERAGE('RC'!G33,'RC'!H33) -> 1296280 | G31: =AVERAGE('RC'!H33,'RC'!I33) -> 470503.5 | H31: =AVERAGE('RC'!I33,'RC'!J33) -> 524933 | I31: =AVERAGE('RC'!I33,'RC'!#REF!) -> #ERROR!
A32: Crediti commerciali medi | B32: =AVERAGE('RC'!C5:D5) -> 4076587.5 | C32: =AVERAGE('RC'!D5:E5) -> 3431489.5 | D32: =AVERAGE('RC'!E5:F5) -> 3073409.5 | E32: =AVERAGE('RC'!F5:G5) -> 2983914 | F32: =AVERAGE('RC'!G5:H5) -> 2715056.5 | G32: =AVERAGE('RC'!H5:I5) -> 2498211 | H32: =AVERAGE('RC'!I5:J5) -> 2367411.5 | I32: =AVERAGE('RC'!J5) -> 2381302
A33: Debiti commerciali medi | B33: =AVERAGE('RC'!C48,'RC'!D48) -> 2308640.5 | C33: =AVERAGE('RC'!D48,'RC'!E48) -> 2430353.5 | D33: =AVERAGE('RC'!E48,'RC'!F48) -> 2329921 | E33: =AVERAGE('RC'!F48,'RC'!G48) -> 1763975.5 | F33: =AVERAGE('RC'!G48,'RC'!H48) -> 1734486 | G33: =AVERAGE('RC'!H48,'RC'!I48) -> 1639495 | H33: =AVERAGE('RC'!I48,'RC'!J48) -> 1229982 | I33: =AVERAGE('RC'!I48,'RC'!#REF!) -> #ERROR!
A34: Rimanenze magazzino medie | B34: =AVERAGE('RC'!C6,'RC'!D6) -> 4824580 | C34: =AVERAGE('RC'!D6,'RC'!E6) -> 5145305 | D34: =AVERAGE('RC'!E6,'RC'!F6) -> 4087317.5 | E34: =AVERAGE('RC'!F6,'RC'!G6) -> 2740524.5 | F34: =AVERAGE('RC'!G6,'RC'!H6) -> 2783699.5 | G34: =AVERAGE('RC'!H6,'RC'!I6) -> 2716481 | H34: =AVERAGE('RC'!I6,'RC'!J6) -> 2246438 | I34: =AVERAGE('RC'!I6,'RC'!#REF!) -> #ERROR!
A35: Rimanenze magazzino finali | B35: ='RC'!C6 -> 4608814 | C35: ='RC'!D6 -> 5040346 | D35: ='RC'!E6 -> 5250264 | E35: ='RC'!F6 -> 2924371 | F35: ='RC'!G6 -> 2556678 | G35: ='RC'!H6 -> 3010721 | H35: ='RC'!I6 -> 2422241 | I35: ='RC'!J6 -> 2070635
A36: Attività a BT | B36: =AVERAGE('RC'!C8:D8)+AVERAGE('RC'!C19:D19)+AVERAGE('RC'!C30:D30) -> 10092731 | C36: =AVERAGE('RC'!D8:E8)+AVERAGE('RC'!D19:E19)+AVERAGE('RC'!D30:E30) -> 10215282 | D36: =AVERAGE('RC'!E8:F8)+AVERAGE('RC'!E19:F19)+AVERAGE('RC'!E30:F30) -> 8159909.5 | E36: =AVERAGE('RC'!F8:G8)+AVERAGE('RC'!F19:G19)+AVERAGE('RC'!F30:G30) -> 6051218.5 | F36: =AVERAGE('RC'!G8:H8)+AVERAGE('RC'!G19:H19)+AVERAGE('RC'!G30:H30) -> 5912189.5 | G36: =AVERAGE('RC'!H8:I8)+AVERAGE('RC'!H19:I19)+AVERAGE('RC'!H30:I30) -> 5504005 | H36: =AVERAGE('RC'!I8:J8)+AVERAGE('RC'!I19:J19)+AVERAGE('RC'!I30:J30) -> 4723640 | I36: =AVERAGE('RC'!J8)+AVERAGE('RC'!J19)+AVERAGE('RC'!J30) -> 4530450
A37: Attività a BT finali | B37: ='RC'!C8+'RC'!C19+'RC'!C30 -> 9705479 | C37: ='RC'!D8+'RC'!D19+'RC'!D30 -> 10479983 | D37: ='RC'!E8+'RC'!E19+'RC'!E30 -> 9950581 | E37: ='RC'!F8+'RC'!F19+'RC'!F30 -> 6369238 | F37: ='RC'!G8+'RC'!G19+'RC'!G30 -> 5733199 | G37: ='RC'!H8+'RC'!H19+'RC'!H30 -> 6091180 | H37: ='RC'!I8+'RC'!I19+'RC'!I30 -> 4916830 | I37: ='RC'!J8+'RC'!J19+'RC'!J30 -> 4530450
A38: Passività a BT medie | B38: =AVERAGE('RC'!C51:D51)+AVERAGE('RC'!C59:D59)+AVERAGE('RC'!C70:D70) -> 8093679.5 | C38: =AVERAGE('RC'!D51:E51)+AVERAGE('RC'!D59:E59)+AVERAGE('RC'!D70:E70) -> 8805614 | D38: =AVERAGE('RC'!E51:F51)+AVERAGE('RC'!E59:F59)+AVERAGE('RC'!E70:F70) -> 7854147.5 | E38: =AVERAGE('RC'!F51:G51)+AVERAGE('RC'!F59:G59)+AVERAGE('RC'!F70:G70) -> 5831649 | F38: =AVERAGE('RC'!G51:H51)+AVERAGE('RC'!G59:H59)+AVERAGE('RC'!G70:H70) -> 5621201 | G38: =AVERAGE('RC'!H51:I51)+AVERAGE('RC'!H59:I59)+AVERAGE('RC'!H70:I70) -> 4908556 | H38: =AVERAGE('RC'!I51:J51)+AVERAGE('RC'!I59:J59)+AVERAGE('RC'!I70:J70) -> 3803690.5 | I38: =AVERAGE('RC'!J51)+AVERAGE('RC'!J59)+AVERAGE('RC'!J70) -> 3922106
A39: Passività a BT finali | B39: ='RC'!C51+'RC'!C59+'RC'!C70 -> 7731693 | C39: ='RC'!D51+'RC'!D59+'RC'!D70 -> 8455666 | D39: ='RC'!E51+'RC'!E59+'RC'!E70 -> 9155562 | E39: ='RC'!F51+'RC'!F59+'RC'!F70 -> 6552733 | F39: ='RC'!G51+'RC'!G59+'RC'!G70 -> 5110565 | G39: ='RC'!H51+'RC'!H59+'RC'!H70 -> 6131837 | H39: ='RC'!I51+'RC'!I59+'RC'!I70 -> 3685275 | I39: ='RC'!J51+'RC'!J59+'RC'!J70 -> 3922106
A40: Passività operative consolidate medie | B40: =AVERAGE('RC'!C52,'RC'!D52) -> 0 | C40: =AVERAGE('RC'!D52,'RC'!E52) -> 0 | D40: =AVERAGE('RC'!E52,'RC'!F52) -> 0 | E40: =AVERAGE('RC'!F52,'RC'!G52) -> 0 | F40: =AVERAGE('RC'!G52,'RC'!H52) -> 0 | G40: =AVERAGE('RC'!H52,'RC'!I52) -> 0 | H40: =AVERAGE('RC'!I52,'RC'!J52) -> 0 | I40: =AVERAGE('RC'!I52,'RC'!#REF!) -> #ERROR!
...

Sheet grph
B3: Quozienti di redditività
B80: Quozienti di rotazione dell'attivo netto
B135: Quozienti di liquidità ed equilibrio fonti/impieghi
B218: Indicatori di robustezza
